2024-04-30 12:13:43,073 - instabot version: 0.117.0 (bot) - INFO - Instabot version: 0.117.0 Started
2024-04-30 12:13:43,073 - instabot version: 0.117.0 (bot) - DEBUG - Bot imported from C:\Users\vansh\AppData\Roaming\Python\Python311\site-packages\instabot\bot\bot.py
2024-04-30 12:13:43,073 - instabot version: 0.117.0 (api_login) - INFO - Not yet logged in starting: PRE-LOGIN FLOW!
2024-04-30 12:13:43,776 - instabot version: 0.117.0 (api) - DEBUG - POST to endpoint: accounts/get_prefill_candidates/ returned response: <Response [429]>
2024-04-30 12:13:43,776 - instabot version: 0.117.0 (api) - DEBUG - Responsecode indicates error; response content: b'{"message":"Please wait a few minutes before you try again.","status":"fail"}'
2024-04-30 12:13:43,776 - instabot version: 0.117.0 (api) - ERROR - Request returns 429 error!
2024-04-30 12:13:43,776 - instabot version: 0.117.0 (api) - WARNING - That means 'too many requests'. I'll go to sleep for 5 minutes.
2024-04-30 12:18:43,789 - instabot version: 0.117.0 (api) - WARNING - HTTPSConnectionPool(host='i.instagram.com', port=443): Max retries exceeded with url: /api/v1/accounts/get_prefill_candidates/ (Caused by NewConnectionError('<urllib3.connection.HTTPSConnection object at 0x0000025867D669D0>: Failed to establish a new connection: [Errno 11001] getaddrinfo failed'))
2024-04-30 12:18:43,791 - instabot version: 0.117.0 (api) - WARNING - HTTPSConnectionPool(host='i.instagram.com', port=443): Max retries exceeded with url: /api/v1/qe/sync/ (Caused by NewConnectionError('<urllib3.connection.HTTPSConnection object at 0x0000025867D6F890>: Failed to establish a new connection: [Errno 11001] getaddrinfo failed'))
2024-04-30 12:18:43,798 - instabot version: 0.117.0 (api) - WARNING - HTTPSConnectionPool(host='i.instagram.com', port=443): Max retries exceeded with url: /api/v1/launcher/sync/ (Caused by NewConnectionError('<urllib3.connection.HTTPSConnection object at 0x0000025868578110>: Failed to establish a new connection: [Errno 11001] getaddrinfo failed'))
2024-04-30 12:18:43,798 - instabot version: 0.117.0 (api) - WARNING - HTTPSConnectionPool(host='i.instagram.com', port=443): Max retries exceeded with url: /api/v1/accounts/contact_point_prefill/ (Caused by NewConnectionError('<urllib3.connection.HTTPSConnection object at 0x0000025868578290>: Failed to establish a new connection: [Errno 11001] getaddrinfo failed'))
